Workbook

Sheet How to use
A1: VITAL Pilot - Budget Worksheet
A3: Purpose: build the budget bottom-up from real quotes, then let the total be whatever it adds up to.
A5: Steps
A6: 1. Go to the 'Budget' tab. For each line, fill in the yellow cells: Unit, Qty, Unit Cost, Months, Status, Tier, Source.
A7: 2. Total is calculated automatically: Qty x Unit Cost x Months (leave Months blank for one-time costs).
A8: 3. Status: Needed = goes in the budget | Later = after the pilot | In-kind = team covers it, no grant money | Not needed.
A9: 4. Tier: Minimum = part of the smallest pilot that still proves the idea | Full = only in the ideal version.
A10: 5. Source: write where the number came from (e.g., 'Quote from ___, Oct 2026' or 'Provider pricing page'). Don't leave it blank.
A11: 6. Need more lines? Use the 'Other (add your own)' rows at the bottom. Keep the Category text exactly as an existing category name, or the line won't be counted on the Summary tab.
A12: 7. The 'Summary' tab shows totals per category, contingency, and Minimum vs Full pilot totals.
A14: Legend
A15: Yellow cells = inputs to fill in
... A22: - Every 'Needed' line should have a Source (Summary tab counts the missing ones).

Sheet Summary
A1: VITAL Pilot - Budget Summary
A3: Contingency (% of subtotal) | B3: 0.1 | C3: Usually 5-10%
A5: Category | B5: Minimum pilot | C5: Full pilot | D5: In-kind (team covers)
A6: Development | B6: =SUMIFS(Budget!$H$2:$H$500,Budget!$A$2:$A$500,$A6,Budget!$I$2:$I$500,"Needed",Budget!$J$2:$J$500,"Minimum") | C6: =SUMIFS(Budget!$H$2:$H$500,Budget!$A$2:$A$500,$A6,Budget!$I$2:$I$500,"Needed") | D6: =SUMIFS(Budget!$H$2:$H$500,Budget!$A$2:$A$500,$A6,Budget!$I$2:$I$500,"In-kind")
A7: Hosting & infrastructure | B7: =SUMIFS(Budget!$H$2:$H$500,Budget!$A$2:$A$500,$A7,Budget!$I$2:$I$500,"Needed",Budget!$J$2:$J$500,"Minimum") | C7: =SUMIFS(Budget!$H$2:$H$500,Budget!$A$2:$A$500,$A7,Budget!$I$2:$I$500,"Needed") | D7: =SUMIFS(Budget!$H$2:$H$500,Budget!$A$2:$A$500,$A7,Budget!$I$2:$I$500,"In-kind")
A8: Services & subscriptions | B8: =SUMIFS(Budget!$H$2:$H$500,Budget!$A$2:$A$500,$A8,Budget!$I$2:$I$500,"Needed",Budget!$J$2:$J$500,"Minimum") | C8: =SUMIFS(Budget!$H$2:$H$500,Budget!$A$2:$A$500,$A8,Budget!$I$2:$I$500,"Needed") | D8: =SUMIFS(Budget!$H$2:$H$500,Budget!$A$2:$A$500,$A8,Budget!$I$2:$I$500,"In-kind")
A9: Security | B9: =SUMIFS(Budget!$H$2:$H$500,Budget!$A$2:$A$500,$A9,Budget!$I$2:$I$500,"Needed",Budget!$J$2:$J$500,"Minimum") | C9: =SUMIFS(Budget!$H$2:$H$500,Budget!$A$2:$A$500,$A9,Budget!$I$2:$I$500,"Needed") | D9: =SUMIFS(Budget!$H$2:$H$500,Budget!$A$2:$A$500,$A9,Budget!$I$2:$I$500,"In-kind")
A10: Legal & privacy | B10: =SUMIFS(Budget!$H$2:$H$500,Budget!$A$2:$A$500,$A10,Budget!$I$2:$I$500,"Needed",Budget!$J$2:$J$500,"Minimum") | C10: =SUMIFS(Budget!$H$2:$H$500,Budget!$A$2:$A$500,$A10,Budget!$I$2:$I$500,"Needed") | D10: =SUMIFS(Budget!$H$2:$H$500,Budget!$A$2:$A$500,$A10,Budget!$I$2:$I$500,"In-kind")
A11: Pilot operations (Bohol) | B11: =SUMIFS(Budget!$H$2:$H$500,Budget!$A$2:$A$500,$A11,Budget!$I$2:$I$500,"Needed",Budget!$J$2:$J$500,"Minimum") | C11: =SUMIFS(Budget!$H$2:$H$500,Budget!$A$2:$A$500,$A11,Budget!$I$2:$I$500,"Needed") | D11: =SUMIFS(Budget!$H$2:$H$500,Budget!$A$2:$A$500,$A11,Budget!$I$2:$I$500,"In-kind")
A12: Support & maintenance | B12: =SUMIFS(Budget!$H$2:$H$500,Budget!$A$2:$A$500,$A12,Budget!$I$2:$I$500,"Needed",Budget!$J$2:$J$500,"Minimum") | C12: =SUMIFS(Budget!$H$2:$H$500,Budget!$A$2:$A$500,$A12,Budget!$I$2:$I$500,"Needed") | D12: =SUMIFS(Budget!$H$2:$H$500,Budget!$A$2:$A$500,$A12,Budget!$I$2:$I$500,"In-kind")
A13: Monitoring & evaluation | B13: =SUMIFS(Budget!$H$2:$H$500,Budget!$A$2:$A$500,$A13,Budget!$I$2:$I$500,"Needed",Budget!$J$2:$J$500,"Minimum") | C13: =SUMIFS(Budget!$H$2:$H$500,Budget!$A$2:$A$500,$A13,Budget!$I$2:$I$500,"Needed") | D13: =SUMIFS(Budget!$H$2:$H$500,Budget!$A$2:$A$500,$A13,Budget!$I$2:$I$500,"In-kind")
A14: Other (add your own) | B14: =SUMIFS(Budget!$H$2:$H$500,Budget!$A$2:$A$500,$A14,Budget!$I$2:$I$500,"Needed",Budget!$J$2:$J$500,"Minimum") | C14: =SUMIFS(Budget!$H$2:$H$500,Budget!$A$2:$A$500,$A14,Budget!$I$2:$I$500,"Needed") | D14: =SUMIFS(Budget!$H$2:$H$500,Budget!$A$2:$A$500,$A14,Budget!$I$2:$I$500,"In-kind")
A15: Subtotal | B15: =SUM(B6:B14) | C15: =SUM(C6:C14) | D15: =SUM(D6:D14)
A16: Contingency | B16: =B15*$B$3 | C16: =C15*$B$3
A17: TOTAL REQUEST | B17: =B15+B16 | C17: =C15+C16
A19: Minimum pilot = 'Needed' items tagged Minimum. Full pilot = all 'Needed' items. In-kind is shown for the proposal narrative, not requested.
A20: 'Needed' lines still missing a Source: | B20: =COUNTIFS(Budget!$I$2:$I$500,"Needed",Budget!$K$2:$K$500,"")

Sheet Budget
A1: Category | B1: Item | C1: What it covers / purpose | D1: Unit | E1: Qty | F1: Unit Cost (PHP) | G1: Months | H1: Total (PHP) | I1: Status | J1: Tier | K1: Source / quote | L1: Notes
A2: Development
A3: Development | B3: Patient app | C3: Referral status, appointment booking, viewing lab results | D3: lot | H3: =IF(OR(E3="",F3=""),0,E3*F3*IF(G3="",1,G3)) | I3: Needed | J3: Minimum
A4: Development | B4: RHU portal | C4: Health workers create referrals and manage appointments | D4: lot | H4: =IF(OR(E4="",F4=""),0,E4*F4*IF(G4="",1,G4)) | I4: Needed | J4: Minimum
A5: Development | B5: Lab results module | C5: Lab uploads results; patient/RHU receives them (upload first, full LIS integration later) | D5: lot | H5: =IF(OR(E5="",F5=""),0,E5*F5*IF(G5="",1,G5)) | I5: Needed | J5: Minimum
A6: Development | B6: Full lab system (LIS) integration | C6: Automatic connection to the lab's existing system | D6: lot | H6: =IF(OR(E6="",F6=""),0,E6*F6*IF(G6="",1,G6)) | I6: Needed | J6: Full
A7: Development | B7: Admin dashboard | C7: User management, basic reports | D7: lot | H7: =IF(OR(E7="",F7=""),0,E7*F7*IF(G7="",1,G7)) | I7: Needed | J7: Full
A8: Development | B8: UI/UX design | C8: Wireframes, prototype, usability testing with RHU staff | D8: lot | H8: =IF(OR(E8="",F8=""),0,E8*F8*IF(G8="",1,G8)) | I8: In-kind | J8: Minimum
A9: Hosting & infrastructure
A10: Hosting & infrastructure | B10: Philippine-hosted cloud server | C10: App + database hosted in a PH data center (data stays in-country) | D10: month | G10: 12 | H10: =IF(OR(E10="",F10=""),0,E10*F10*IF(G10="",1,G10)) | I10: Needed | J10: Minimum
A11: Hosting & infrastructure | B11: Backups | C11: Daily encrypted backups | D11: month | G11: 12 | H11: =IF(OR(E11="",F11=""),0,E11*F11*IF(G11="",1,G11)) | I11: Needed | J11: Minimum
A12: Hosting & infrastructure | B12: Domain + SSL | C12: Web address and HTTPS certificate | D12: year | H12: =IF(OR(E12="",F12=""),0,E12*F12*IF(G12="",1,G12)) | I12: Needed | J12: Minimum
A13: Hosting & infrastructure | B13: Staging / test environment | C13: Separate environment for testing before release | D13: month | G13: 12 | H13: =IF(OR(E13="",F13=""),0,E13*F13*IF(G13="",1,G13)) | I13: Needed | J13: Full
A14: Services & subscriptions
A15: Services & subscriptions | B15: SMS gateway | C15: Appointment reminders and result alerts (Qty = number of messages) | D15: message | H15: =IF(OR(E15="",F15=""),0,E15*F15*IF(G15="",1,G15)) | I15: Needed | J15: Minimum
A16: Services & subscriptions | B16: Email service | C16: Account and notification emails | D16: month | G16: 12 | H16: =IF(OR(E16="",F16=""),0,E16*F16*IF(G16="",1,G16)) | I16: Later | J16: Full
A17: Services & subscriptions | B17: Google Play developer account | C17: Publish Android app (one-time fee) | D17: account | H17: =IF(OR(E17="",F17=""),0,E17*F17*IF(G17="",1,G17)) | I17: Needed | J17: Minimum
A18: Services & subscriptions | B18: Apple developer account | C18: Publish iOS app (yearly fee) | D18: year | H18: =IF(OR(E18="",F18=""),0,E18*F18*IF(G18="",1,G18)) | I18: Later | J18: Full
A19: Security
A20: Security | B20: Basic vulnerability scan | C20: Check for common security issues before real patient data goes in | D20: lot | H20: =IF(OR(E20="",F20=""),0,E20*F20*IF(G20="",1,G20)) | I20: Needed | J20: Minimum
A21: Security | B21: Penetration test | C21: Professional security test | D21: lot | H21: =IF(OR(E21="",F21=""),0,E21*F21*IF(G21="",1,G21)) | I21: Later | J21: Full
A22: Legal & privacy
A23: Legal & privacy | B23: Privacy Impact Assessment | C23: Review of how patient data is collected, stored and shared | D23: lot | H23: =IF(OR(E23="",F23=""),0,E23*F23*IF(G23="",1,G23)) | I23: Needed | J23: Minimum
A24: Legal & privacy | B24: Data-sharing agreements | C24: With each RHU/clinic and the partner lab | D24: agreement | H24: =IF(OR(E24="",F24=""),0,E24*F24*IF(G24="",1,G24)) | I24: Needed | J24: Minimum
A25: Legal & privacy | B25: Privacy policy, terms, consent forms | C25: Patient-facing documents | D25: lot | H25: =IF(OR(E25="",F25=""),0,E25*F25*IF(G25="",1,G25)) | I25: Needed | J25: Minimum
A26: Legal & privacy | B26: NPC registration / DPO setup | C26: Register with National Privacy Commission; designate a Data Protection Officer | D26: lot | H26: =IF(OR(E26="",F26=""),0,E26*F26*IF(G26="",1,G26)) | I26: Needed | J26: Minimum
A27: Legal & privacy | B27: Legal review | C27: Lawyer review of agreements and policies | D27: lot | H27: =IF(OR(E27="",F27=""),0,E27*F27*IF(G27="",1,G27)) | I27: Needed | J27: Minimum
A28: Pilot operations (Bohol)
A29: Pilot operations (Bohol) | B29: Travel to pilot sites | C29: Fare, lodging, meals per site visit | D29: trip | E29: 4 | F29: 3500 | H29: =IF(OR(E29="",F29=""),0,E29*F29*IF(G29="",1,G29)) | I29: Needed | J29: Minimum | K29: EXAMPLE ONLY - replace with your real fare/lodging estimate | L29: e.g., 2 sites x 2 visits
A30: Pilot operations (Bohol) | B30: Staff training sessions | C30: Training for RHU and lab staff (venue, snacks) | D30: session | H30: =IF(OR(E30="",F30=""),0,E30*F30*IF(G30="",1,G30)) | I30: Needed | J30: Minimum
A31: Pilot operations (Bohol) | B31: Training materials | C31: Manuals, quick-reference cards, videos | D31: lot | H31: =IF(OR(E31="",F31=""),0,E31*F31*IF(G31="",1,G31)) | I31: Needed | J31: Minimum
A32: Pilot operations (Bohol) | B32: Patient materials | C32: Posters, flyers, printed consent forms | D32: lot | H32: =IF(OR(E32="",F32=""),0,E32*F32*IF(G32="",1,G32)) | I32: Needed | J32: Minimum
A33: Pilot operations (Bohol) | B33: Connectivity allowance | C33: Load/data for health workers during the pilot | D33: month | H33: =IF(OR(E33="",F33=""),0,E33*F33*IF(G33="",1,G33)) | I33: Needed | J33: Full
A34: Pilot operations (Bohol) | B34: Devices for sites | C34: Tablets/phones only if sites lack them (check that the grant allows equipment) | D34: unit | H34: =IF(OR(E34="",F34=""),0,E34*F34*IF(G34="",1,G34)) | I34: Later | J34: Full
A35: Support & maintenance
A36: Support & maintenance | B36: Bug fixes & helpdesk during pilot | C36: Fixing issues and answering RHU staff questions after launch | D36: month | H36: =IF(OR(E36="",F36=""),0,E36*F36*IF(G36="",1,G36)) | I36: Needed | J36: Minimum
A37: Monitoring & evaluation
A38: Monitoring & evaluation | B38: Baseline + pilot data collection | C38: Measure referral/result turnaround before and during the pilot | D38: lot | H38: =IF(OR(E38="",F38=""),0,E38*F38*IF(G38="",1,G38)) | I38: In-kind | J38: Minimum
A39: Monitoring & evaluation | B39: Surveys & final pilot report | C39: User feedback and results report | D39: lot | H39: =IF(OR(E39="",F39=""),0,E39*F39*IF(G39="",1,G39)) | I39: In-kind | J39: Minimum
A40: Other (add your own)
...
